{
 "cells": [
  {
   "cell_type": "markdown",
   "metadata": {},
   "source": [
    "### CS 665 Final Project\n",
    "\n",
    "Seth Lewis, Nick Netterville, Carment Saunders, Laura Thompson  \n",
    "CS 665, Deep Learning  \n",
    "SPR 2022, 04/21/2022   "
   ]
  },
  {
   "cell_type": "markdown",
   "metadata": {},
   "source": [
    "# Data Generation\n",
    "\n",
    "The purpose of this notebook is to generate the image data used to train, test, and validate our model.\n",
    "\n",
    "The final data consists of [TODO] images. [TODO] of these images are labeled '1' (positive data) indicating an image of a crowd that is socially distanced. The remaining [TODO] images are labeled '0' (negative data) indicating an image of a crowd that is not socially distancing."
   ]
  },
  {
   "cell_type": "markdown",
   "metadata": {},
   "source": [
    "## Data Collection Methods"
   ]
  },
  {
   "cell_type": "markdown",
   "metadata": {},
   "source": [
    "### Negative Data\n",
    "\n",
    "The negative data (images of crowds not socially distancing) for this project was collected from an existing dataset, [JHU-Crowd++](http://www.crowd-counting.com/#download) which is a dataset primarily used for crowd counting. For the purposes of our experiment, we collected the first 1000 training images from this dataset that met the following criteria:  \n",
    "- More than 3 people in the image (crowd)\n",
    "- The crowd is densly packed (most people are within 6ft of each other)\n",
    "- Image is taken from crowd level, not above\n",
    "- No Severe blurring\n",
    "- No Severe weather conditions\n",
    "- Most people in the image are not obscured by other features\n",
    "\n",
    "For more details on the exact imlementation of this, see `get_negatives.py`"
   ]
  },
  {
   "cell_type": "code",
   "execution_count": null,
   "metadata": {},
   "outputs": [
    {
     "data": {
      "application/javascript": "IPython.notebook.clear_all_output();\n",
      "text/plain": [
       "<IPython.core.display.Javascript object>"
      ]
     },
     "metadata": {},
     "output_type": "display_data"
    }
   ],
   "source": [
    "%%javascript\n",
    "IPython.notebook.clear_all_output();"
   ]
  },
  {
   "cell_type": "code",
   "execution_count": null,
   "metadata": {},
   "outputs": [],
   "source": [
    "from preprocessing_scripts.get_negatives import get_negative_data\n",
    "\n",
    "#run only if jhu data is present in this directory\n",
    "get_negative_data(\"jhu_crowd_v2.0\", \"negative_data\")"
   ]
  },
  {
   "cell_type": "markdown",
   "metadata": {},
   "source": [
    "### Positive Data\n",
    "\n",
    "The positive data for this experiment was collected manually by searching for images of people social distancing. The criteria for these images are the same as the criteria for the negative data, except that a majority of the crowd must be standing away from one another, e.g. sparsely packed."
   ]
  },
  {
   "cell_type": "markdown",
   "metadata": {},
   "source": [
    "## Data Augmentation"
   ]
  },
  {
   "cell_type": "markdown",
   "metadata": {},
   "source": [
    "### Negative Data\n",
    "\n",
    "Due to the significantly larger number of negative images available for this problem, we have initially chosen not to perform any augmentation on the negative images in order to increase the data size."
   ]
  },
  {
   "cell_type": "markdown",
   "metadata": {},
   "source": [
    "### Positive Data\n",
    "\n",
    "Because the positive data set is notably smaller than the negative data set, we elected to augment the positive data in several different ways in order to increase the number of positive images to be comparable to the number of negative images. The following methods were used to augment the positive data:\n",
    "- flipping\n",
    "- mirroring\n",
    "- adding noise\n",
    "- cropping\n",
    "- [TODO]"
   ]
  },
  {
   "cell_type": "code",
   "execution_count": 4,
   "metadata": {},
   "outputs": [
    {
     "ename": "FileNotFoundError",
     "evalue": "[Errno 2] No such file or directory: '46800.jpeg' -> '46800.jpg'",
     "output_type": "error",
     "traceback": [
      "\u001b[0;31m---------------------------------------------------------------------------\u001b[0m",
      "\u001b[0;31mFileNotFoundError\u001b[0m                         Traceback (most recent call last)",
      "\u001b[0;32m/tmp/ipykernel_45161/3614527887.py\u001b[0m in \u001b[0;36m<module>\u001b[0;34m\u001b[0m\n\u001b[1;32m      4\u001b[0m     \u001b[0mfile_ext\u001b[0m \u001b[0;34m=\u001b[0m \u001b[0mpositive\u001b[0m\u001b[0;34m.\u001b[0m\u001b[0msplit\u001b[0m\u001b[0;34m(\u001b[0m\u001b[0;34m'.'\u001b[0m\u001b[0;34m)\u001b[0m\u001b[0;34m[\u001b[0m\u001b[0;36m1\u001b[0m\u001b[0;34m]\u001b[0m\u001b[0;34m\u001b[0m\u001b[0;34m\u001b[0m\u001b[0m\n\u001b[1;32m      5\u001b[0m     \u001b[0;32mif\u001b[0m \u001b[0mfile_ext\u001b[0m \u001b[0;34m!=\u001b[0m \u001b[0;34m\"jpg\"\u001b[0m\u001b[0;34m:\u001b[0m\u001b[0;34m\u001b[0m\u001b[0;34m\u001b[0m\u001b[0m\n\u001b[0;32m----> 6\u001b[0;31m         \u001b[0mrename\u001b[0m\u001b[0;34m(\u001b[0m\u001b[0mpositive\u001b[0m\u001b[0;34m,\u001b[0m \u001b[0;34mf\"{positive.split('.')[0]}.jpg\"\u001b[0m\u001b[0;34m)\u001b[0m\u001b[0;34m\u001b[0m\u001b[0;34m\u001b[0m\u001b[0m\n\u001b[0m",
      "\u001b[0;31mFileNotFoundError\u001b[0m: [Errno 2] No such file or directory: '46800.jpeg' -> '46800.jpg'"
     ]
    }
   ],
   "source": [
    "# Need to rename .jpeg's to .jpg\n",
    "\n",
    "\n",
    "from os import rename, listdir\n",
    "positives = listdir(\"./positive_data\")\n",
    "for positive in positives:\n",
    "    file_ext = positive.split('.')[1]\n",
    "    if file_ext != \"jpg\":\n",
    "        rename(positive, f\"{positive.split('.')[0]}.jpg\")"
   ]
  },
  {
   "cell_type": "markdown",
   "metadata": {},
   "source": [
    "## Combining Positive and Negative Data\n",
    "\n",
    "The final step in generating our data set was to take the negative dataset and augmented positive dataset and combine them to create a final `data` directory containing an `image_labels.csv` file of image labels of the form `<img_number>, <label>` corresponding to each image in an `images` directory named `<img_number>.jpg`\n",
    "\n",
    "The final image data is randomly ordered."
   ]
  },
  {
   "cell_type": "code",
   "execution_count": 5,
   "metadata": {},
   "outputs": [
    {
     "name": "stderr",
     "output_type": "stream",
     "text": [
      "ERROR:root:Internal Python error in the inspect module.\n",
      "Below is the traceback from this internal error.\n",
      "\n",
      "ERROR:root:Internal Python error in the inspect module.\n",
      "Below is the traceback from this internal error.\n",
      "\n",
      "ERROR:root:Internal Python error in the inspect module.\n",
      "Below is the traceback from this internal error.\n",
      "\n"
     ]
    },
    {
     "name": "stdout",
     "output_type": "stream",
     "text": [
      "Traceback (most recent call last):\n",
      "  File \"/home/laurthompson0/Documents/CS665/Final/cs665-final/preprocessing_scripts/combine_data.py\", line 60, in shuffle_imgs\n",
      "    tempdir, join(imgdir, \"images\"), label[0] + \".jpg\", ind + offset + 1\n",
      "  File \"/home/laurthompson0/Documents/CS665/Final/cs665-final/preprocessing_scripts/combine_data.py\", line 33, in copy_rename\n",
      "    image = load_img(old_path, target_size=(224, 224))  # Resize\n",
      "  File \"/home/laurthompson0/.miniconda3/envs/cs665final/lib/python3.7/site-packages/keras_preprocessing/image/utils.py\", line 113, in load_img\n",
      "    with open(path, 'rb') as f:\n",
      "FileNotFoundError: [Errno 2] No such file or directory: 'data/images_temp_train/1237.jpg'\n",
      "\n",
      "During handling of the above exception, another exception occurred:\n",
      "\n",
      "Traceback (most recent call last):\n",
      "  File \"/home/laurthompson0/.miniconda3/envs/cs665final/lib/python3.7/site-packages/IPython/core/interactiveshell.py\", line 3457, in run_code\n",
      "    exec(code_obj, self.user_global_ns, self.user_ns)\n",
      "  File \"/tmp/ipykernel_45161/2767623312.py\", line 4, in <module>\n",
      "    combine(dirs=[\"negative_data\", \"positive_data\"],augmentation_functions=AUGMENTATION_FUNCTIONS, split=0.8, shuffle_labels=True) # Negative data MUST come first for labeling purposes\n",
      "  File \"/home/laurthompson0/Documents/CS665/Final/cs665-final/preprocessing_scripts/combine_data.py\", line 168, in combine\n",
      "    label_info[0], label_info[1], label_info[2], offset, shuffle_labels\n",
      "  File \"/home/laurthompson0/Documents/CS665/Final/cs665-final/preprocessing_scripts/combine_data.py\", line 64, in shuffle_imgs\n",
      "    tempdir, join(imgdir, \"images\"), label[0] + \".png\", ind + offset + 1\n",
      "  File \"/home/laurthompson0/Documents/CS665/Final/cs665-final/preprocessing_scripts/combine_data.py\", line 33, in copy_rename\n",
      "    image = load_img(old_path, target_size=(224, 224))  # Resize\n",
      "  File \"/home/laurthompson0/.miniconda3/envs/cs665final/lib/python3.7/site-packages/keras_preprocessing/image/utils.py\", line 113, in load_img\n",
      "    with open(path, 'rb') as f:\n",
      "FileNotFoundError: [Errno 2] No such file or directory: 'data/images_temp_train/1237.png'\n",
      "\n",
      "During handling of the above exception, another exception occurred:\n",
      "\n",
      "Traceback (most recent call last):\n",
      "  File \"/home/laurthompson0/.miniconda3/envs/cs665final/lib/python3.7/site-packages/IPython/core/interactiveshell.py\", line 2077, in showtraceback\n",
      "    stb = value._render_traceback_()\n",
      "AttributeError: 'FileNotFoundError' object has no attribute '_render_traceback_'\n",
      "\n",
      "During handling of the above exception, another exception occurred:\n",
      "\n",
      "Traceback (most recent call last):\n",
      "  File \"/home/laurthompson0/.miniconda3/envs/cs665final/lib/python3.7/site-packages/IPython/core/ultratb.py\", line 1101, in get_records\n",
      "    return _fixed_getinnerframes(etb, number_of_lines_of_context, tb_offset)\n",
      "  File \"/home/laurthompson0/.miniconda3/envs/cs665final/lib/python3.7/site-packages/IPython/core/ultratb.py\", line 248, in wrapped\n",
      "    return f(*args, **kwargs)\n",
      "  File \"/home/laurthompson0/.miniconda3/envs/cs665final/lib/python3.7/site-packages/IPython/core/ultratb.py\", line 281, in _fixed_getinnerframes\n",
      "    records = fix_frame_records_filenames(inspect.getinnerframes(etb, context))\n",
      "  File \"/home/laurthompson0/.miniconda3/envs/cs665final/lib/python3.7/inspect.py\", line 1502, in getinnerframes\n",
      "    frameinfo = (tb.tb_frame,) + getframeinfo(tb, context)\n",
      "  File \"/home/laurthompson0/.miniconda3/envs/cs665final/lib/python3.7/inspect.py\", line 1460, in getframeinfo\n",
      "    filename = getsourcefile(frame) or getfile(frame)\n",
      "  File \"/home/laurthompson0/.miniconda3/envs/cs665final/lib/python3.7/inspect.py\", line 696, in getsourcefile\n",
      "    if getattr(getmodule(object, filename), '__loader__', None) is not None:\n",
      "  File \"/home/laurthompson0/.miniconda3/envs/cs665final/lib/python3.7/inspect.py\", line 733, in getmodule\n",
      "    if ismodule(module) and hasattr(module, '__file__'):\n",
      "  File \"/home/laurthompson0/.miniconda3/envs/cs665final/lib/python3.7/site-packages/tensorflow/__init__.py\", line 50, in __getattr__\n",
      "    module = self._load()\n",
      "  File \"/home/laurthompson0/.miniconda3/envs/cs665final/lib/python3.7/site-packages/tensorflow/__init__.py\", line 44, in _load\n",
      "    module = _importlib.import_module(self.__name__)\n",
      "  File \"/home/laurthompson0/.miniconda3/envs/cs665final/lib/python3.7/importlib/__init__.py\", line 127, in import_module\n",
      "    return _bootstrap._gcd_import(name[level:], package, level)\n",
      "  File \"<frozen importlib._bootstrap>\", line 1006, in _gcd_import\n",
      "  File \"<frozen importlib._bootstrap>\", line 983, in _find_and_load\n",
      "  File \"<frozen importlib._bootstrap>\", line 965, in _find_and_load_unlocked\n",
      "ModuleNotFoundError: No module named 'tensorflow_core.estimator'\n",
      "Traceback (most recent call last):\n",
      "  File \"/home/laurthompson0/Documents/CS665/Final/cs665-final/preprocessing_scripts/combine_data.py\", line 60, in shuffle_imgs\n",
      "    tempdir, join(imgdir, \"images\"), label[0] + \".jpg\", ind + offset + 1\n",
      "  File \"/home/laurthompson0/Documents/CS665/Final/cs665-final/preprocessing_scripts/combine_data.py\", line 33, in copy_rename\n",
      "    image = load_img(old_path, target_size=(224, 224))  # Resize\n",
      "  File \"/home/laurthompson0/.miniconda3/envs/cs665final/lib/python3.7/site-packages/keras_preprocessing/image/utils.py\", line 113, in load_img\n",
      "    with open(path, 'rb') as f:\n",
      "FileNotFoundError: [Errno 2] No such file or directory: 'data/images_temp_train/1237.jpg'\n",
      "\n",
      "During handling of the above exception, another exception occurred:\n",
      "\n",
      "Traceback (most recent call last):\n",
      "  File \"/home/laurthompson0/.miniconda3/envs/cs665final/lib/python3.7/site-packages/IPython/core/interactiveshell.py\", line 3457, in run_code\n",
      "    exec(code_obj, self.user_global_ns, self.user_ns)\n",
      "  File \"/tmp/ipykernel_45161/2767623312.py\", line 4, in <module>\n",
      "    combine(dirs=[\"negative_data\", \"positive_data\"],augmentation_functions=AUGMENTATION_FUNCTIONS, split=0.8, shuffle_labels=True) # Negative data MUST come first for labeling purposes\n",
      "  File \"/home/laurthompson0/Documents/CS665/Final/cs665-final/preprocessing_scripts/combine_data.py\", line 168, in combine\n",
      "    label_info[0], label_info[1], label_info[2], offset, shuffle_labels\n",
      "  File \"/home/laurthompson0/Documents/CS665/Final/cs665-final/preprocessing_scripts/combine_data.py\", line 64, in shuffle_imgs\n",
      "    tempdir, join(imgdir, \"images\"), label[0] + \".png\", ind + offset + 1\n",
      "  File \"/home/laurthompson0/Documents/CS665/Final/cs665-final/preprocessing_scripts/combine_data.py\", line 33, in copy_rename\n",
      "    image = load_img(old_path, target_size=(224, 224))  # Resize\n",
      "  File \"/home/laurthompson0/.miniconda3/envs/cs665final/lib/python3.7/site-packages/keras_preprocessing/image/utils.py\", line 113, in load_img\n",
      "    with open(path, 'rb') as f:\n",
      "FileNotFoundError: [Errno 2] No such file or directory: 'data/images_temp_train/1237.png'\n",
      "\n",
      "During handling of the above exception, another exception occurred:\n",
      "\n",
      "Traceback (most recent call last):\n",
      "  File \"/home/laurthompson0/.miniconda3/envs/cs665final/lib/python3.7/site-packages/IPython/core/interactiveshell.py\", line 2077, in showtraceback\n",
      "    stb = value._render_traceback_()\n",
      "AttributeError: 'FileNotFoundError' object has no attribute '_render_traceback_'\n",
      "\n",
      "During handling of the above exception, another exception occurred:\n",
      "\n",
      "Traceback (most recent call last):\n",
      "  File \"/home/laurthompson0/.miniconda3/envs/cs665final/lib/python3.7/site-packages/IPython/core/interactiveshell.py\", line 3377, in run_ast_nodes\n",
      "    if (await self.run_code(code, result,  async_=asy)):\n",
      "  File \"/home/laurthompson0/.miniconda3/envs/cs665final/lib/python3.7/site-packages/IPython/core/interactiveshell.py\", line 3474, in run_code\n",
      "    self.showtraceback(running_compiled_code=True)\n",
      "  File \"/home/laurthompson0/.miniconda3/envs/cs665final/lib/python3.7/site-packages/IPython/core/interactiveshell.py\", line 2080, in showtraceback\n",
      "    value, tb, tb_offset=tb_offset)\n",
      "  File \"/home/laurthompson0/.miniconda3/envs/cs665final/lib/python3.7/site-packages/IPython/core/ultratb.py\", line 1368, in structured_traceback\n",
      "    self, etype, value, tb, tb_offset, number_of_lines_of_context)\n",
      "  File \"/home/laurthompson0/.miniconda3/envs/cs665final/lib/python3.7/site-packages/IPython/core/ultratb.py\", line 1268, in structured_traceback\n",
      "    self, etype, value, tb, tb_offset, number_of_lines_of_context\n",
      "  File \"/home/laurthompson0/.miniconda3/envs/cs665final/lib/python3.7/site-packages/IPython/core/ultratb.py\", line 1125, in structured_traceback\n",
      "    tb_offset)\n",
      "  File \"/home/laurthompson0/.miniconda3/envs/cs665final/lib/python3.7/site-packages/IPython/core/ultratb.py\", line 1082, in format_exception_as_a_whole\n",
      "    last_unique, recursion_repeat = find_recursion(orig_etype, evalue, records)\n",
      "  File \"/home/laurthompson0/.miniconda3/envs/cs665final/lib/python3.7/site-packages/IPython/core/ultratb.py\", line 382, in find_recursion\n",
      "    return len(records), 0\n",
      "TypeError: object of type 'NoneType' has no len()\n",
      "\n",
      "During handling of the above exception, another exception occurred:\n",
      "\n",
      "Traceback (most recent call last):\n",
      "  File \"/home/laurthompson0/.miniconda3/envs/cs665final/lib/python3.7/site-packages/IPython/core/interactiveshell.py\", line 2077, in showtraceback\n",
      "    stb = value._render_traceback_()\n",
      "AttributeError: 'TypeError' object has no attribute '_render_traceback_'\n",
      "\n",
      "During handling of the above exception, another exception occurred:\n",
      "\n",
      "Traceback (most recent call last):\n",
      "  File \"/home/laurthompson0/.miniconda3/envs/cs665final/lib/python3.7/site-packages/IPython/core/ultratb.py\", line 1101, in get_records\n",
      "    return _fixed_getinnerframes(etb, number_of_lines_of_context, tb_offset)\n",
      "  File \"/home/laurthompson0/.miniconda3/envs/cs665final/lib/python3.7/site-packages/IPython/core/ultratb.py\", line 248, in wrapped\n",
      "    return f(*args, **kwargs)\n",
      "  File \"/home/laurthompson0/.miniconda3/envs/cs665final/lib/python3.7/site-packages/IPython/core/ultratb.py\", line 281, in _fixed_getinnerframes\n",
      "    records = fix_frame_records_filenames(inspect.getinnerframes(etb, context))\n",
      "  File \"/home/laurthompson0/.miniconda3/envs/cs665final/lib/python3.7/inspect.py\", line 1502, in getinnerframes\n",
      "    frameinfo = (tb.tb_frame,) + getframeinfo(tb, context)\n",
      "  File \"/home/laurthompson0/.miniconda3/envs/cs665final/lib/python3.7/inspect.py\", line 1460, in getframeinfo\n",
      "    filename = getsourcefile(frame) or getfile(frame)\n",
      "  File \"/home/laurthompson0/.miniconda3/envs/cs665final/lib/python3.7/inspect.py\", line 696, in getsourcefile\n",
      "    if getattr(getmodule(object, filename), '__loader__', None) is not None:\n",
      "  File \"/home/laurthompson0/.miniconda3/envs/cs665final/lib/python3.7/inspect.py\", line 733, in getmodule\n",
      "    if ismodule(module) and hasattr(module, '__file__'):\n",
      "  File \"/home/laurthompson0/.miniconda3/envs/cs665final/lib/python3.7/site-packages/tensorflow/__init__.py\", line 50, in __getattr__\n",
      "    module = self._load()\n",
      "  File \"/home/laurthompson0/.miniconda3/envs/cs665final/lib/python3.7/site-packages/tensorflow/__init__.py\", line 44, in _load\n",
      "    module = _importlib.import_module(self.__name__)\n",
      "  File \"/home/laurthompson0/.miniconda3/envs/cs665final/lib/python3.7/importlib/__init__.py\", line 127, in import_module\n",
      "    return _bootstrap._gcd_import(name[level:], package, level)\n",
      "  File \"<frozen importlib._bootstrap>\", line 1006, in _gcd_import\n",
      "  File \"<frozen importlib._bootstrap>\", line 983, in _find_and_load\n",
      "  File \"<frozen importlib._bootstrap>\", line 965, in _find_and_load_unlocked\n",
      "ModuleNotFoundError: No module named 'tensorflow_core.estimator'\n",
      "Traceback (most recent call last):\n",
      "  File \"/home/laurthompson0/Documents/CS665/Final/cs665-final/preprocessing_scripts/combine_data.py\", line 60, in shuffle_imgs\n",
      "    tempdir, join(imgdir, \"images\"), label[0] + \".jpg\", ind + offset + 1\n",
      "  File \"/home/laurthompson0/Documents/CS665/Final/cs665-final/preprocessing_scripts/combine_data.py\", line 33, in copy_rename\n",
      "    image = load_img(old_path, target_size=(224, 224))  # Resize\n",
      "  File \"/home/laurthompson0/.miniconda3/envs/cs665final/lib/python3.7/site-packages/keras_preprocessing/image/utils.py\", line 113, in load_img\n",
      "    with open(path, 'rb') as f:\n",
      "FileNotFoundError: [Errno 2] No such file or directory: 'data/images_temp_train/1237.jpg'\n",
      "\n",
      "During handling of the above exception, another exception occurred:\n",
      "\n",
      "Traceback (most recent call last):\n",
      "  File \"/home/laurthompson0/.miniconda3/envs/cs665final/lib/python3.7/site-packages/IPython/core/interactiveshell.py\", line 3457, in run_code\n",
      "    exec(code_obj, self.user_global_ns, self.user_ns)\n",
      "  File \"/tmp/ipykernel_45161/2767623312.py\", line 4, in <module>\n",
      "    combine(dirs=[\"negative_data\", \"positive_data\"],augmentation_functions=AUGMENTATION_FUNCTIONS, split=0.8, shuffle_labels=True) # Negative data MUST come first for labeling purposes\n",
      "  File \"/home/laurthompson0/Documents/CS665/Final/cs665-final/preprocessing_scripts/combine_data.py\", line 168, in combine\n",
      "    label_info[0], label_info[1], label_info[2], offset, shuffle_labels\n",
      "  File \"/home/laurthompson0/Documents/CS665/Final/cs665-final/preprocessing_scripts/combine_data.py\", line 64, in shuffle_imgs\n",
      "    tempdir, join(imgdir, \"images\"), label[0] + \".png\", ind + offset + 1\n",
      "  File \"/home/laurthompson0/Documents/CS665/Final/cs665-final/preprocessing_scripts/combine_data.py\", line 33, in copy_rename\n",
      "    image = load_img(old_path, target_size=(224, 224))  # Resize\n",
      "  File \"/home/laurthompson0/.miniconda3/envs/cs665final/lib/python3.7/site-packages/keras_preprocessing/image/utils.py\", line 113, in load_img\n",
      "    with open(path, 'rb') as f:\n",
      "FileNotFoundError: [Errno 2] No such file or directory: 'data/images_temp_train/1237.png'\n",
      "\n",
      "During handling of the above exception, another exception occurred:\n",
      "\n",
      "Traceback (most recent call last):\n",
      "  File \"/home/laurthompson0/.miniconda3/envs/cs665final/lib/python3.7/site-packages/IPython/core/interactiveshell.py\", line 2077, in showtraceback\n",
      "    stb = value._render_traceback_()\n",
      "AttributeError: 'FileNotFoundError' object has no attribute '_render_traceback_'\n",
      "\n",
      "During handling of the above exception, another exception occurred:\n",
      "\n",
      "Traceback (most recent call last):\n",
      "  File \"/home/laurthompson0/.miniconda3/envs/cs665final/lib/python3.7/site-packages/IPython/core/interactiveshell.py\", line 3377, in run_ast_nodes\n",
      "    if (await self.run_code(code, result,  async_=asy)):\n",
      "  File \"/home/laurthompson0/.miniconda3/envs/cs665final/lib/python3.7/site-packages/IPython/core/interactiveshell.py\", line 3474, in run_code\n",
      "    self.showtraceback(running_compiled_code=True)\n",
      "  File \"/home/laurthompson0/.miniconda3/envs/cs665final/lib/python3.7/site-packages/IPython/core/interactiveshell.py\", line 2080, in showtraceback\n",
      "    value, tb, tb_offset=tb_offset)\n",
      "  File \"/home/laurthompson0/.miniconda3/envs/cs665final/lib/python3.7/site-packages/IPython/core/ultratb.py\", line 1368, in structured_traceback\n",
      "    self, etype, value, tb, tb_offset, number_of_lines_of_context)\n",
      "  File \"/home/laurthompson0/.miniconda3/envs/cs665final/lib/python3.7/site-packages/IPython/core/ultratb.py\", line 1268, in structured_traceback\n",
      "    self, etype, value, tb, tb_offset, number_of_lines_of_context\n",
      "  File \"/home/laurthompson0/.miniconda3/envs/cs665final/lib/python3.7/site-packages/IPython/core/ultratb.py\", line 1125, in structured_traceback\n",
      "    tb_offset)\n",
      "  File \"/home/laurthompson0/.miniconda3/envs/cs665final/lib/python3.7/site-packages/IPython/core/ultratb.py\", line 1082, in format_exception_as_a_whole\n",
      "    last_unique, recursion_repeat = find_recursion(orig_etype, evalue, records)\n",
      "  File \"/home/laurthompson0/.miniconda3/envs/cs665final/lib/python3.7/site-packages/IPython/core/ultratb.py\", line 382, in find_recursion\n",
      "    return len(records), 0\n",
      "TypeError: object of type 'NoneType' has no len()\n",
      "\n",
      "During handling of the above exception, another exception occurred:\n",
      "\n",
      "Traceback (most recent call last):\n",
      "  File \"/home/laurthompson0/.miniconda3/envs/cs665final/lib/python3.7/site-packages/IPython/core/interactiveshell.py\", line 2077, in showtraceback\n",
      "    stb = value._render_traceback_()\n",
      "AttributeError: 'TypeError' object has no attribute '_render_traceback_'\n",
      "\n",
      "During handling of the above exception, another exception occurred:\n",
      "\n",
      "Traceback (most recent call last):\n",
      "  File \"/home/laurthompson0/.miniconda3/envs/cs665final/lib/python3.7/site-packages/IPython/core/interactiveshell.py\", line 2960, in _run_cell\n",
      "    return runner(coro)\n",
      "  File \"/home/laurthompson0/.miniconda3/envs/cs665final/lib/python3.7/site-packages/IPython/core/async_helpers.py\", line 78, in _pseudo_sync_runner\n",
      "    coro.send(None)\n",
      "  File \"/home/laurthompson0/.miniconda3/envs/cs665final/lib/python3.7/site-packages/IPython/core/interactiveshell.py\", line 3186, in run_cell_async\n",
      "    interactivity=interactivity, compiler=compiler, result=result)\n",
      "  File \"/home/laurthompson0/.miniconda3/envs/cs665final/lib/python3.7/site-packages/IPython/core/interactiveshell.py\", line 3396, in run_ast_nodes\n",
      "    self.showtraceback()\n",
      "  File \"/home/laurthompson0/.miniconda3/envs/cs665final/lib/python3.7/site-packages/IPython/core/interactiveshell.py\", line 2080, in showtraceback\n",
      "    value, tb, tb_offset=tb_offset)\n",
      "  File \"/home/laurthompson0/.miniconda3/envs/cs665final/lib/python3.7/site-packages/IPython/core/ultratb.py\", line 1368, in structured_traceback\n",
      "    self, etype, value, tb, tb_offset, number_of_lines_of_context)\n",
      "  File \"/home/laurthompson0/.miniconda3/envs/cs665final/lib/python3.7/site-packages/IPython/core/ultratb.py\", line 1268, in structured_traceback\n",
      "    self, etype, value, tb, tb_offset, number_of_lines_of_context\n",
      "  File \"/home/laurthompson0/.miniconda3/envs/cs665final/lib/python3.7/site-packages/IPython/core/ultratb.py\", line 1143, in structured_traceback\n",
      "    chained_exceptions_tb_offset)\n",
      "  File \"/home/laurthompson0/.miniconda3/envs/cs665final/lib/python3.7/site-packages/IPython/core/ultratb.py\", line 1082, in format_exception_as_a_whole\n",
      "    last_unique, recursion_repeat = find_recursion(orig_etype, evalue, records)\n",
      "  File \"/home/laurthompson0/.miniconda3/envs/cs665final/lib/python3.7/site-packages/IPython/core/ultratb.py\", line 382, in find_recursion\n",
      "    return len(records), 0\n",
      "TypeError: object of type 'NoneType' has no len()\n",
      "\n",
      "During handling of the above exception, another exception occurred:\n",
      "\n",
      "Traceback (most recent call last):\n",
      "  File \"/home/laurthompson0/.miniconda3/envs/cs665final/lib/python3.7/site-packages/IPython/core/interactiveshell.py\", line 2077, in showtraceback\n",
      "    stb = value._render_traceback_()\n",
      "AttributeError: 'TypeError' object has no attribute '_render_traceback_'\n",
      "\n",
      "During handling of the above exception, another exception occurred:\n",
      "\n",
      "Traceback (most recent call last):\n",
      "  File \"/home/laurthompson0/.miniconda3/envs/cs665final/lib/python3.7/site-packages/IPython/core/ultratb.py\", line 1101, in get_records\n",
      "    return _fixed_getinnerframes(etb, number_of_lines_of_context, tb_offset)\n",
      "  File \"/home/laurthompson0/.miniconda3/envs/cs665final/lib/python3.7/site-packages/IPython/core/ultratb.py\", line 248, in wrapped\n",
      "    return f(*args, **kwargs)\n",
      "  File \"/home/laurthompson0/.miniconda3/envs/cs665final/lib/python3.7/site-packages/IPython/core/ultratb.py\", line 281, in _fixed_getinnerframes\n",
      "    records = fix_frame_records_filenames(inspect.getinnerframes(etb, context))\n",
      "  File \"/home/laurthompson0/.miniconda3/envs/cs665final/lib/python3.7/inspect.py\", line 1502, in getinnerframes\n",
      "    frameinfo = (tb.tb_frame,) + getframeinfo(tb, context)\n",
      "  File \"/home/laurthompson0/.miniconda3/envs/cs665final/lib/python3.7/inspect.py\", line 1460, in getframeinfo\n",
      "    filename = getsourcefile(frame) or getfile(frame)\n",
      "  File \"/home/laurthompson0/.miniconda3/envs/cs665final/lib/python3.7/inspect.py\", line 696, in getsourcefile\n",
      "    if getattr(getmodule(object, filename), '__loader__', None) is not None:\n",
      "  File \"/home/laurthompson0/.miniconda3/envs/cs665final/lib/python3.7/inspect.py\", line 733, in getmodule\n",
      "    if ismodule(module) and hasattr(module, '__file__'):\n",
      "  File \"/home/laurthompson0/.miniconda3/envs/cs665final/lib/python3.7/site-packages/tensorflow/__init__.py\", line 50, in __getattr__\n",
      "    module = self._load()\n",
      "  File \"/home/laurthompson0/.miniconda3/envs/cs665final/lib/python3.7/site-packages/tensorflow/__init__.py\", line 44, in _load\n",
      "    module = _importlib.import_module(self.__name__)\n",
      "  File \"/home/laurthompson0/.miniconda3/envs/cs665final/lib/python3.7/importlib/__init__.py\", line 127, in import_module\n",
      "    return _bootstrap._gcd_import(name[level:], package, level)\n",
      "  File \"<frozen importlib._bootstrap>\", line 1006, in _gcd_import\n",
      "  File \"<frozen importlib._bootstrap>\", line 983, in _find_and_load\n",
      "  File \"<frozen importlib._bootstrap>\", line 965, in _find_and_load_unlocked\n",
      "ModuleNotFoundError: No module named 'tensorflow_core.estimator'\n"
     ]
    }
   ],
   "source": [
    "from preprocessing_scripts.combine_data import combine\n",
    "from preprocessing_scripts.augmentation_functions import AUGMENTATION_FUNCTIONS\n",
    "\n",
    "combine(dirs=[\"negative_data\", \"positive_data\"],augmentation_functions=AUGMENTATION_FUNCTIONS, split=0.8, shuffle_labels=True) # Negative data MUST come first for labeling purposes"
   ]
  },
  {
   "cell_type": "code",
   "execution_count": null,
   "metadata": {},
   "outputs": [],
   "source": []
  }
 ],
 "metadata": {
  "interpreter": {
   "hash": "a73c24dfce9a0f4c1e875b890d068c026a947d4805d80159e81d47d053081c89"
  },
  "kernelspec": {
   "display_name": "Python [conda env:cs665final]",
   "language": "python",
   "name": "conda-env-cs665final-py"
  },
  "language_info": {
   "codemirror_mode": {
    "name": "ipython",
    "version": 3
   },
   "file_extension": ".py",
   "mimetype": "text/x-python",
   "name": "python",
   "nbconvert_exporter": "python",
   "pygments_lexer": "ipython3",
   "version": "3.7.13"
  }
 },
 "nbformat": 4,
 "nbformat_minor": 2
}
